Workbook

Sheet Summary
A1: Kindlescout run: AI-feasible Kindle categories (top 20 per category)
A3: Snapshot captured | B3: 2026-10-07 15:34 UTC (Amazon.com, US store). One snapshot only: BSR moves hourly.
A4: Scope (per user) | B4: Top 20 paid Kindle titles per category; only categories where AI-generated digital products can feasibly succeed (see Category_Screen).
A5: Access mode | B5: Amazon-native via HTTP (no browser tools). Best Sellers pages + 167 product pages fetched directly with a cookie session. Amazon critical-review filter pages require sign-in, so review mining uses the reviews shown on product pages (2,059 reviews, 123 rated 1-3★) plus Goodreads. Category_Mix (overall Kindle top 100) omitted: out of the user's scope.
A6: Confidence | B6: High for snapshot facts (rank, price, KU, pages, publisher field). Medium for sales estimates (third-party BSR curve, ±40% band). Publisher class is inferred where the Kindle page lists no publisher. No concept can reach Tier A until a second snapshot exists.
A7: KDP rule: 70% royalty band | B7: Verified 2026-10-07 at kdp.amazon.com/en_US/help/topic/G200634560: "Effective July 7, 2026, the 70% royalty option price band is $2.99-$12.99 on Amazon.com" (was $2.99-$9.99). Delivery costs still apply to 70%; outside the band = 35%.
A8: KDP rule: delivery cost | B8: Verified 2026-10-07 at kdp.amazon.com/en_US/help/topic/G200634500: Amazon.com US $0.15/MB (70% option only).
A9: KDP rule: AI content | B9: Verified 2026-10-07 at kdp.amazon.com/en_US/help/topic/G200672390: AI-generated text, images or translations must be disclosed "even if you applied substantial edits afterwards"; AI-assisted (you wrote it, AI edited/brainstormed) need not be. Enforcement escalated April 2026 (writeo.app, Aug 2026): undisclosed titles removed without warning. Upload cap of 3 new titles/day confirmed by KDP to the Authors Guild (Sep 2023).
A10: KDP rule: Nigeria payments | B10: Verified 2026-10-07 at kdp.amazon.com/en_US/help/topic/GJD7DFFX6X88AK46: Nigeria = wire transfer in NGN for all listed marketplaces; no direct deposit or cheque; nothing for Amazon.pl / .se.
A11: KU economics | B11: KDP Select Global Fund Aug 2026: $66.0M, $0.005170 per KENP page (Written Word Media, updated 2026-09-18). KDP site footer: total KDP Select author earnings Aug 2026 $69.4M (includes bonuses).
A13: TOP FINDINGS
A14: 1. Where indie/AI-era titles actually chart | B14: Of 200 top-20 slots, indie titles (inferred) hold: Prayer 2, Stress 5, Self-Esteem 5, Motivational 1, Affirmations 2, Journaling 6, Time Mgmt 4, Nutrition 6, Quick & Easy 1, Short Reads 13. Nutrition is the standout: all 6 indie titles were published in the last 18 months.
A15: 2. The winning indie format | B15: Short-to-mid guides (75-190 pages), $4.99-9.99, enrolled in KU, in a series. Examples: Spiritual Warfare Prayers From the Psalms (75pp, $4.99, BSR 11,842); Let Them Go (81pp, $5.99, BSR 10,862); High-Protein Cottage Cheese Cookbook (100pp, $9.99, BSR 9,789).
A16: 3. Readers now name AI in reviews | B16: 5 of 123 critical reviews on these pages explicitly call the book AI-written, including traditional titles (e.g. "Reads like AI slop."; "Clearly written by AI... some good ideas but weird vibe."). Detectable AI prose is now a review-level liability.
A17: 4. The complaint gap AI-assisted products can fill | B17: Repetition and padding ("80% of them were the same prompt reworded"), no editing ("numerous instances where the same sentences..."), thin content ("29 pages of lists"), untested recipes, broken bonus downloads. Editorial quality, not volume, is the gap.
A18: 5. Supply is saturated | B18: Originality.ai: 77% of new "Success" self-help titles (Aug-Nov 2025) and 63% of new religious titles (Jan-Jun 2026) likely AI-written. Likely-AI books averaged 26 reviews vs 129 for human-written. Raw AI output competes in the long tail, not the top 20.
A19: 6. Best concepts (all Tier B pending a 2nd snapshot) | B19: See Opportunities: (1) Gentle emotional-detachment / overthinking guide series, (2) Trend-diet companion cookbooks with full nutrition panels, (3) Non-clinical ADHD executive-function workbook. Prayer-points series scores just under B but carries a Nigeria-voice edge.
A20: 7. Delivery fees punish image-heavy ebooks | B20: At $0.15/MB, the 52.8 MB High-Protein Cottage Cheese Cookbook earns more on 35% than on 70% ($3.50 vs ~-$0.93 per sale). Several America's Test Kitchen titles exceed 400 MB. Keep cookbook ebooks image-light (<5 MB) and put photos in print.
A21: 8. $0.99 launch noise | B21: Four 2026 titles (9 Hidden Switches, One Brave Breath, I Don't Eat That, Cheap and Wicked Good!) rank on $0.99 launch pricing with 10-31 reviews. Treat their ranks as promotion spikes until a second snapshot confirms they hold.
A23: How to use this workbook | B23: Blue cells on Sales_Estimates, BSR_Table and Opportunities are editable inputs. Charts_Snapshot is the raw capture. Sales and royalty columns are formulas and recalculate when inputs change.

Sheet Category_Screen
A1: Category | B1: Kindle node | C1: Decision | D1: Reason (AI feasibility)
A2: Prayer | B2: 158562011 | C2: Include | D2: Formulaic, scripture-anchored structure (prayer points, declarations); indie titles 75-126pp rank in top 20; Nigerian authors already rank (Kindle Ranker list: Tella Olayeri, Tomi Arayomi). Needs a real ministry voice + scripture accuracy check.
A3: Stress Management | B3: 156574011 | C3: Include | D3: Indie "mental habits" guides (Meurisse, Chidiac) rank top 20; practical-technique format suits AI drafting + heavy human editing. Avoid clinical claims.
A4: Self-Esteem | B4: 156572011 | C4: Include | D4: Five indie titles in top 20 incl. 2025-26 entrants (Logan West, Laura Falces). Complaints are about repetition and editing, which an edited product can fix.
A5: Motivational | B5: 156570011 | C5: Include (benchmark) | D5: Included to test; snapshot shows 19/20 traditional or classic titles, so it serves as a "do not enter head-on" benchmark.
A6: Affirmations | B6: 202437591011 | C6: Include | D6: Short, list-based format; one 2025 indie title in top 10 whose reviewer suspects AI. New node, not on Kindle Ranker.
A7: Journaling | B7: 11650899011 | C7: Include | D7: Prompt/template products are AI-friendly; 6/20 indie; low thresholds (Kindle Ranker #1 ~12/day). Ebook format limits writable journals except Kindle Scribe.
A8: Time Management | B8: 202437598011 | C8: Include | D8: Indie ADHD workbooks and a Kindle Scribe planner rank; ManuscriptReport: 70% indie, #1 needs 29-80/day.
A9: Nutrition | B9: 156497011 | C9: Include | D9: 6/20 indie, all published in the last 18 months: trend-diet companions and cookbooks. Recipes must be human-tested; health claims need care.
A10: Quick & Easy (Cookbooks) | B10: 156202011 | C10: Include (benchmark) | D10: Recipe format is AI-draftable but buyers punish untested recipes; snapshot shows America's Test Kitchen and big publishers at $0.99-5.99.
A11: One-Hour Self-Help Short Reads | B11: 8624198011 | C11: Include (funnel only) | D11: Short-read format is easiest to produce but the #1 sells ~8/day; useful only as a lead-in to a series.
A12: ADHD (Health) | B12: 11717478011 | C12: Exclude | D12: Medical/diagnostic claims; buyers and Amazon policy penalise generic content. ADHD productivity is covered via Time Management instead.
... A17: Memoir / Biographies | B17: - | C17: Exclude | D17: Requires a real life story; AI generation is inappropriate and non-competitive.

Sheet Charts_Snapshot
A1: Key | B1: Category | C1: Node | D1: Rank | E1: Title | F1: Author | G1: Publisher (Kindle page) | H1: Publisher class (inferred) | I1: ASIN | J1: Price ($) | K1: Stars | L1: Reviews | M1: Kindle Store BSR | N1: KU | O1: Print length (pp) | P1: File size (MB) | Q1: Publication date | R1: Months since publication | S1: Formats | T1: Category ranks (product page) | U1: Product URL | W1: Capture date
A2: =B2&"|"&D2 -> Prayer|1 | B2: Prayer | C2: 158562011 | D2: 1 | E2: Contemplative Prayer (Image Classic) | F2: Thomas Merton | G2: Image | H2: Traditional/established press | I2: B002VD6NJ6 | J2: 1.99 | K2: 4.5 | L2: 502 | M2: 6841 | N2: N | O2: 146 | P2: 1.8 | Q2: 40120 | R2: =IF(Q2="","",($W$2-Q2)/30.44) -> 203.08804 | S2: HARDCOVER, KINDLE, MASS_MARKET_PAPERBACK, PAPERBACK | T2: #1 in Christian Monasticism & Asceticism (Kindle Store); #1 in Prayer (Kindle Store); #2 in Christian Monasticism & Asceticism (Books) | U2: https://www.amazon.com/dp/B002VD6NJ6 | W2: 46302
A3: =B3&"|"&D3 -> Prayer|2 | B3: Prayer | C3: 158562011 | D3: 2 | E3: Praying Like Monks, Living Like Fools: An Invitation to the Wonder and Mystery of Prayer | F3: Tyler Staton | G3: Thomas Nelson | H3: Traditional/established press | I3: B09XX2H1KL | J3: 4.99 | K3: 4.8 | L3: 3510 | M3: 8407 | N3: Y | O3: 272 | P3: 4.1 | Q3: 44838 | R3: =IF(Q3="","",($W$2-Q3)/30.44) -> 48.094612 | S3: AUDIO_DOWNLOAD, KINDLE, PAPERBACK, SPIRAL_BOUND | T3: #1 in Inspirational Prayer; #2 in Prayer (Kindle Store); #2 in Christian Prayer (Kindle Store) | U3: https://www.amazon.com/dp/B09XX2H1KL
A4: =B4&"|"&D4 -> Prayer|3 | B4: Prayer | C4: 158562011 | D4: 3 | E4: Praying the Names of God for 52 Weeks, Expanded Edition: A Year-Long Bible Study | F4: Ann Spangler | G4: HarperChristian Resources | H4: Traditional/established press | I4: B0982Z4P74 | J4: 1.99 | K4: 4.8 | L4: 1748 | M4: 10079 | N4: N | O4: 295 | P4: 9.2 | Q4: 45062 | R4: =IF(Q4="","",($W$2-Q4)/30.44) -> 40.735874 | S4: KINDLE, PAPERBACK | T4: #2 in Christian Prayer Books (Kindle Store); #2 in Prayer (Books); #3 in Christian Prayer Books (Books) | U4: https://www.amazon.com/dp/B0982Z4P74
A5: =B5&"|"&D5 -> Prayer|4 | B5: Prayer | C5: 158562011 | D5: 4 | E5: The Familiar Stranger: (Re)Introducing the Holy Spirit to Those in Search of an Experiential Spirituality | F5: Tyler Staton | G5: Thomas Nelson | H5: Traditional/established press | I5: B0CZ42CXKK | J5: 3.99 | K5: 4.8 | L5: 1265 | M5: 10680 | N5: N | O5: 256 | P5: 1.3 | Q5: 45685 | R5: =IF(Q5="","",($W$2-Q5)/30.44) -> 20.269382 | S5: AUDIO_DOWNLOAD, HARDCOVER, KINDLE, PAPERBACK | T5: #1 in Pneumatology Christian Theology; #2 in Christian Pneumatology; #2 in Inspirational Prayer | U5: https://www.amazon.com/dp/B0CZ42CXKK
A6: =B6&"|"&D6 -> Prayer|5 | B6: Prayer | C6: 158562011 | D6: 5 | E6: Breath as Prayer: Calm Your Anxiety, Focus Your Mind, and Renew Your Soul (80+ Breath Prayers and Devotional Meditations) | F6: Jennifer Tucker | G6: Thomas Nelson | H6: Traditional/established press | I6: B09N945BWH | J6: 3.99 | K6: 4.8 | L6: 2380 | M6: 11490 | N6: Y | O6: 201 | P6: 9.4 | Q6: 44817 | R6: =IF(Q6="","",($W$2-Q6)/30.44) -> 48.784494 | S6: AUDIOBOOK, AUDIO_DOWNLOAD, HARDCOVER, KINDLE | T6: #3 in Christian Prayer Books (Kindle Store); #3 in Inspirational Prayer; #3 in Prayer (Books) | U6: https://www.amazon.com/dp/B09N945BWH
A7: =B7&"|"&D7 -> Prayer|6 | B7: Prayer | C7: 158562011 | D7: 6 | E7: Spiritual Warfare Prayers From the Psalms: Finding Strength, Protection, and Breakthrough in God's Word - A Devotional Guide for God's Covering, Provision, Wisdom, Courage, and Cleansing | F7: Ephesians 521 Ministries | G7: (none listed) | H7: Indie (no publisher listed) | I7: B0F4KJLXPQ | J7: 4.99 | K7: 4.8 | L7: 482 | M7: 11842 | N7: Y | O7: 75 | P7: 2.3 | Q7: 45758 | R7: =IF(Q7="","",($W$2-Q7)/30.44) -> 17.871222 | S7: AUDIO_DOWNLOAD, KINDLE, PAPERBACK, SPIRAL_BOUND | T7: #4 in Christian Prayer Books (Kindle Store); #6 in Prayer (Kindle Store); #8 in Two-Hour Religion & Spirituality Short Reads | U7: https://www.amazon.com/dp/B0F4KJLXPQ
A8: =B8&"|"&D8 -> Prayer|7 | B8: Prayer | C8: 158562011 | D8: 7 | E8: Principles of Prayer | F8: Charles G. Finney | G8: Bethany House Publishers | H8: Traditional/established press | I8: B00B85AIYY | J8: 3.99 | K8: 4.8 | L8: 218 | M8: 12101 | N8: N | O8: 128 | P8: 0.53 | Q8: 36951 | R8: =IF(Q8="","",($W$2-Q8)/30.44) -> 307.19448 | S8: KINDLE, PAPERBACK | T8: #5 in Christian Prayer Books (Kindle Store); #6 in Spiritual Devotionals; #7 in Prayer (Kindle Store) | U8: https://www.amazon.com/dp/B00B85AIYY
A9: =B9&"|"&D9 -> Prayer|8 | B9: Prayer | C9: 158562011 | D9: 8 | E9: Pray First: The Transformative Power of a Life Built on Prayer | F9: Chris Hodges | G9: Thomas Nelson | H9: Traditional/established press | I9: B0B35VP9G9 | J9: 2.99 | K9: 4.8 | L9: 1515 | M9: 12423 | N9: Y | O9: 272 | P9: 7.3 | Q9: 44922 | R9: =IF(Q9="","",($W$2-Q9)/30.44) -> 45.335085 | S9: AUDIOBOOK, AUDIO_DOWNLOAD, KINDLE, PAPERBACK | T9: #4 in Inspirational Prayer; #4 in Hebrew Bible (Old Testament) Meditations; #5 in Christian Old Testament Meditations | U9: https://www.amazon.com/dp/B0B35VP9G9
A10: =B10&"|"&D10 -> Prayer|9 | B10: Prayer | C10: 158562011 | D10: 9 | E10: The Game of Life and How to Play It: The Original Unabridged And Complete Edition (Florence Scovel Shinn Classics) | F10: Florence Scovel Shinn | G10: Tech Tok Ltd | H10: Public-domain reprint | I10: B0CFPY9QTW | J10: 0.99 | K10: 4.8 | L10: 5222 | M10: 12807 | N10: N | O10: 75 | P10: 0.41 | Q10: 45193 | R10: =IF(Q10="","",($W$2-Q10)/30.44) -> 36.432326 | S10: KINDLE, PAPERBACK | T10: #1 in Religious Studies - Ethics; #7 in Religious Ethics (Books); #9 in Prayer (Kindle Store) | U10: https://www.amazon.com/dp/B0CFPY9QTW
A11: =B11&"|"&D11 -> Prayer|10 | B11: Prayer | C11: 158562011 | D11: 10 | E11: A Shepherd Looks at Psalm 23: Discovering God's Love for You (Timeless Faith Classics) | F11: W. Phillip Keller | G11: Zondervan | H11: Traditional/established press | I11: B001EH5YRM | J11: 1.99 | K11: 4.8 | L11: 7682 | M11: 12809 | N11: Y | O11: 131 | P11: 12.5 | Q11: 39677 | R11: =IF(Q11="","",($W$2-Q11)/30.44) -> 217.64126 | S11: AUDIO_DOWNLOAD, HARDCOVER, KINDLE, MASS_MARKET_PAPERBACK | T11: #2 in Christian Wisdom Literature (Books); #2 in Christian Wisdom Literature (Kindle Store); #4 in Old Testament Meditations | U11: https://www.amazon.com/dp/B001EH5YRM
A12: =B12&"|"&D12 -> Prayer|11 | B12: Prayer | C12: 158562011 | D12: 11 | E12: Trusting God with Today: A Daily Devotional for Building Confident Faith and Lasting Joy (365 Devotions - Inspiration for Every Day of the Year) (Devotionals from Charles F. Stanley) | F12: Charles F. Stanley | G12: Thomas Nelson | H12: Traditional/established press | I12: B0BYYWYDFJ | J12: 3.99 | K12: 4.9 | L12: 1346 | M12: 16726 | N12: Y | O12: 381 | P12: 1.1 | Q12: 45223 | R12: =IF(Q12="","",($W$2-Q12)/30.44) -> 35.446781 | S12: AUDIO_DOWNLOAD, HARDCOVER, KINDLE | T12: #7 in Christian New Testament Meditations; #8 in Hebrew Bible (Old Testament) Meditations; #9 in Christian Old Testament Meditations | U12: https://www.amazon.com/dp/B0BYYWYDFJ
A13: =B13&"|"&D13 -> Prayer|12 | B13: Prayer | C13: 158562011 | D13: 12 | E13: How to Hear God: A Simple Guide for Normal People | F13: Pete Greig | G13: Zondervan | H13: Traditional/established press | I13: B0982ZQR1C | J13: 1.99 | K13: 4.8 | L13: 1376 | M13: 19206 | N13: Y | O13: 272 | P13: 2.1 | Q13: 44621 | R13: =IF(Q13="","",($W$2-Q13)/30.44) -> 55.22339 | S13: AUDIOBOOK, AUDIO_DOWNLOAD, KINDLE, PAPERBACK | T13: #5 in Christian Rites & Ceremonies; #5 in Jesus, the Gospels & Acts (Kindle Store); #6 in Christian Meditation Worship & Devotion (Kindle Store) | U13: https://www.amazon.com/dp/B0982ZQR1C
A14: =B14&"|"&D14 -> Prayer|13 | B14: Prayer | C14: 158562011 | D14: 13 | E14: Jesus Listens: Daily Devotional Prayers of Peace, Joy, and Hope (A 365-Day Prayer Book) | F14: Sarah Young | G14: Thomas Nelson | H14: Traditional/established press | I14: B08ZMCQ3VH | J14: 3.99 | K14: 4.8 | L14: 10335 | M14: 21263 | N14: Y | O14: 392 | P14: 1.2 | Q14: 44474 | R14: =IF(Q14="","",($W$2-Q14)/30.44) -> 60.052562 | S14: AUDIOBOOK, AUDIO_DOWNLOAD, HARDCOVER, KINDLE | T14: #6 in Prayer (Books); #7 in New Testament Meditations; #7 in Old Testament Meditations | U14: https://www.amazon.com/dp/B08ZMCQ3VH
... A84: =B84&"|"&D84 -> Affirmations|3 | B84: Affirmations | C84: 202437591011 | D84: 3 | E84: Unfu*k Yourself: Get Out of Your Head and into Your Life – The New York Times Bestselling Tough-Love Self-Help Guide to Stop Self-Sabotage and Boost Resilience (Unfu*k Yourself series Book 1) | F84: Gary John Bishop | G84: HarperOne | H84: Traditional/established press | I84: B071F7C5NQ | J84: 13.99 | K84: 4.6 | L84: 28900 | M84: 7307 | N84: Y | O84: 218 | P84: 2.1 | Q84: 42948 | R84: =IF(Q84="","",($W$2-Q84)/30.44) -> 110.18397 | S84: AUDIO_DOWNLOAD, HARDCOVER, KINDLE, PAPERBACK | T84: #1 in Positive Psychology eBooks; #2 in Family & Personal Growth; #3 in Self-Help Affirmations eBooks | U84: https://www.amazon.com/dp/B071F7C5NQ
A85: =B85&"|"&D85 -> Affirmations|4 | B85: Affirmations | C85: 202437591011 | D85: 4 | E85: The Force That Guides The Stars: 108 Quotes from Indian Sage P.R. Sarkar (Yoga Wisdom Series) | F85: Kate Kusuma Donnelly | G85: Ananda Arts Fund | H85: Indie imprint (inferred) | I85: B0HHFM6KS4 | J85: 4.99 | M85: 14682 | N85: Y | O85: 126 | P85: 0.64 | Q85: 46297 | R85: =IF(Q85="","",($W$2-Q85)/30.44) -> 0.16425756 | S85: KINDLE, PAPERBACK | T85: #4 in Self-Help Affirmations eBooks; #27 in Self-Esteem Self-Help; #33 in Spiritual Self-Help (Kindle Store) | U85: https://www.amazon.com/dp/B0HHFM6KS4
A86: =B86&"|"&D86 -> Affirmations|5 | B86: Affirmations | C86: 202437591011 | D86: 5 | E86: A Year to Clear: A Daily Guide to Creating Spaciousness in Your Home and Heart (Hierophant Space Clearing) | F86: Stephanie Bennett Vogt | G86: Hierophant Publishing | H86: Traditional/established press | I86: B0145Z4WZO | J86: 0.99 | K86: 4.4 | L86: 278 | M86: 21441 | N86: N | O86: 378 | P86: 2.1 | Q86: 42278 | R86: =IF(Q86="","",($W$2-Q86)/30.44) -> 132.19448 | S86: AUDIO_DOWNLOAD, KINDLE, PAPERBACK | T86: #5 in Self-Help Affirmations eBooks; #9 in Personal Transformation & Spirituality; #27 in Spiritual Growth Self-Help | U86: https://www.amazon.com/dp/B0145Z4WZO
A87: =B87&"|"&D87 -> Affirmations|6 | B87: Affirmations | C87: 202437591011 | D87: 6 | E87: The Complete Works of Florence Scovel Shinn: The Game of Life and How to Play It; Your Word Is Your Wand; The Secret Door to Success; and The Power of the Spoken Word | F87: Florence Scovel Shinn | G87: Grapevine (08th January, 2026) | H87: Public-domain reprint | I87: B0GFP5XR4R | J87: 0.51 | K87: 4.8 | L87: 7061 | M87: 24223 | N87: N | O87: 197 | P87: 0.55 | Q87: 46030 | R87: =IF(Q87="","",($W$2-Q87)/30.44) -> 8.935611 | S87: AUDIO_DOWNLOAD, HARDCOVER, KINDLE, PAPERBACK | T87: #1 in Mysticism (Kindle Store); #6 in Self-Help Affirmations eBooks; #33 in Mysticism (Books) | U87: https://www.amazon.com/dp/B0GFP5XR4R
A88: =B88&"|"&D88 -> Affirmations|7 | B88: Affirmations | C88: 202437591011 | D88: 7 | E88: Self-Compassion: The Proven Power of Being Kind to Yourself | F88: Kristin Neff | G88: William Morrow | H88: Traditional/established press | I88: B004JN1DBO | J88: 13.99 | K88: 4.6 | L88: 7281 | M88: 25438 | N88: N | O88: 320 | P88: 2.1 | Q88: 40652 | R88: =IF(Q88="","",($W$2-Q88)/30.44) -> 185.61104 | S88: AUDIO_DOWNLOAD, HARDCOVER, KINDLE, PAPERBACK | T88: #7 in Self-Help Affirmations eBooks; #8 in Social Philosophy; #11 in Meditation (Kindle Store) | U88: https://www.amazon.com/dp/B004JN1DBO
A89: =B89&"|"&D89 -> Affirmations|8 | B89: Affirmations | C89: 202437591011 | D89: 8 | E89: The Soft Life Handbook: A Feminine Guide to Slow Living, Boundaries, and Romanticizing Your Life | F89: Airy Fairy Press | G89: (none listed) | H89: Indie (no publisher listed) | I89: B0FHGR45BK | J89: 7.88 | K89: 4.4 | L89: 448 | M89: 27484 | N89: Y | O89: 84 | P89: 0.55 | Q89: 45851 | R89: =IF(Q89="","",($W$2-Q89)/30.44) -> 14.816032 | S89: HARDCOVER, KINDLE, PAPERBACK | T89: #8 in Self-Help Affirmations eBooks; #12 in Two-Hour Self-Help Short Reads; #52 in Self-Esteem Self-Help | U89: https://www.amazon.com/dp/B0FHGR45BK
A90: =B90&"|"&D90 -> Affirmations|9 | B90: Affirmations | C90: 202437591011 | D90: 9 | E90: Life's Journeys According to Mister Rogers: Things to Remember Along the Way | F90: Fred Rogers | G90: Balance | H90: Traditional/established press | I90: B00CKUEVSK | J90: 2.99 | K90: 4.8 | L90: 1029 | M90: 30708 | N90: N | O90: 177 | P90: 2.7 | Q90: 41443 | R90: =IF(Q90="","",($W$2-Q90)/30.44) -> 159.62549 | S90: AUDIOBOOK, AUDIO_DOWNLOAD, HARDCOVER, KINDLE | T90: #9 in Self-Help Affirmations eBooks; #28 in Ethics & Morality; #37 in Parenting (Kindle Store) | U90: https://www.amazon.com/dp/B00CKUEVSK
A91: =B91&"|"&D91 -> Affirmations|10 | B91: Affirmations | C91: 202437591011 | D91: 10 | E91: Your Word is Your Wand | F91: Florence Scovel Shinn | G91: SANAGE PUBLISHING HOUSE LLP | H91: Public-domain reprint | I91: B08RZBQXRD | J91: 0.25 | K91: 4.6 | L91: 814 | M91: 34201 | N91: N | O91: 52 | P91: 0.62 | Q91: 44199 | R91: =IF(Q91="","",($W$2-Q91)/30.44) -> 69.086728 | S91: AUDIO_DOWNLOAD, HARDCOVER, KINDLE, PAPERBACK | T91: #4 in 90-Minute Self-Help Short Reads; #10 in Self-Help Affirmations eBooks; #64 in Self-Esteem Self-Help | U91: https://www.amazon.com/dp/B08RZBQXRD
A92: =B92&"|"&D92 -> Affirmations|11 | B92: Affirmations | C92: 202437591011 | D92: 11 | E92: I’m Still Here: A Dog's Purpose Forever | F92: Cathryn Michon | G92: Andrews McMeel Publishing | H92: Traditional/established press | I92: B0D82F72YY | J92: 1.99 | K92: 4.7 | L92: 1488 | M92: 35280 | N92: N | O92: 125 | P92: 56.5 | Q92: 45545 | R92: =IF(Q92="","",($W$2-Q92)/30.44) -> 24.868594 | S92: AUDIO_DOWNLOAD, HARDCOVER, KINDLE | T92: #8 in Pet Dogs; #11 in Self-Help Affirmations eBooks; #17 in Dog Care | U92: https://www.amazon.com/dp/B0D82F72YY
A93: =B93&"|"&D93 -> Affirmations|12 | B93: Affirmations | C93: 202437591011 | D93: 12 | E93: Warrior Goddess Wisdom: Daily Inspiration for Women | F93: HeatherAsh Amara | G93: Hierophant Publishing | H93: Traditional/established press | I93: B07CV4V8HN | J93: 0.99 | K93: 4.8 | L93: 632 | M93: 41032 | N93: N | O93: 205 | P93: 3.9 | Q93: 43435 | R93: =IF(Q93="","",($W$2-Q93)/30.44) -> 94.185283 | S93: AUDIO_DOWNLOAD, KINDLE, PAPERBACK | T93: #3 in New Age Goddesses (Kindle Store); #6 in Shamanism (Kindle Store); #12 in Self-Help Affirmations eBooks | U93: https://www.amazon.com/dp/B07CV4V8HN
A94: =B94&"|"&D94 -> Affirmations|13 | B94: Affirmations | C94: 202437591011 | D94: 13 | E94: Earth, Air, Fire & Water: More Techniques of Natural Magic (Llewellyn's Practical Magick Series) | F94: Scott Cunningham | G94: Llewellyn Publications | H94: Traditional/established press | I94: B00A29FZHC | J94: 3.99 | K94: 4.8 | L94: 1489 | M94: 45787 | N94: Y | O94: 186 | P94: 4.2 | Q94: 41221 | R94: =IF(Q94="","",($W$2-Q94)/30.44) -> 166.91853 | S94: AUDIOBOOK, AUDIO_DOWNLOAD, KINDLE, PAPERBACK | T94: #13 in Self-Help Affirmations eBooks; #18 in Alchemy; #20 in Folklore & Mythology | U94: https://www.amazon.com/dp/B00A29FZHC
A95: =B95&"|"&D95 -> Affirmations|14 | B95: Affirmations | C95: 202437591011 | D95: 14 | E95: El poder del ahora / The Power of Now: Un camino hacia la realizacion espiritual / A Guide to Spiritual Enlightenment (Spanish Edition) | F95: Eckhart Tolle | G95: New World Library | H95: Traditional/established press | I95: B00472O4M2 | J95: 9.03 | K95: 4.7 | L95: 18271 | M95: 55618 | N95: N | O95: 131 | P95: 3.2 | Q95: 40445 | R95: =IF(Q95="","",($W$2-Q95)/30.44) -> 192.4113 | S95: AUDIOBOOK, AUDIO_DOWNLOAD, KINDLE, PAPERBACK | T95: #3 in Mysticism & Spirituality; #4 in Society & Social Sciences in Spanish; #7 in Foreign Language Instruction (Books) | U95: https://www.amazon.com/dp/B00472O4M2
A96: =B96&"|"&D96 -> Affirmations|15 | B96: Affirmations | C96: 202437591011 | D96: 15 | E96: The Hero Code: Lessons Learned from Lives Well Lived | F96: Admiral William H. McRaven | G96: Grand Central Publishing | H96: Traditional/established press | I96: B08GKDJ6RQ | J96: 12.99 | K96: 4.8 | L96: 4348 | M96: 63153 | N96: N | O96: 177 | P96: 0.74 | Q96: 44299 | R96: =IF(Q96="","",($W$2-Q96)/30.44) -> 65.801577 | S96: AUDIOBOOK, AUDIO_DOWNLOAD, HARDCOVER, KINDLE | T96: #15 in Self-Help Affirmations eBooks; #19 in Biographies of the Military Navy; #91 in Self-Esteem (Books) | U96: https://www.amazon.com/dp/B08GKDJ6RQ
A97: =B97&"|"&D97 -> Affirmations|16 | B97: Affirmations | C97: 202437591011 | D97: 16 | E97: You Can Heal Your Life | F97: Louise L. Hay | G97: Hay House LLC | H97: Traditional/established press | I97: B000SEHQ96 | J97: 10.99 | K97: 4.7 | L97: 23352 | M97: 64715 | N97: N | O97: 235 | P97: 2.5 | Q97: 34765 | R97: =IF(Q97="","",($W$2-Q97)/30.44) -> 379.00788 | S97: AUDIO_DOWNLOAD, HARDCOVER, KINDLE, PAPERBACK | T97: #10 in New Thought; #16 in Self-Help Affirmations eBooks; #20 in Love & Loss | U97: https://www.amazon.com/dp/B000SEHQ96
... A103: =B103&"|"&D103 -> Journaling|2 | B103: Journaling | C103: 11650899011 | D103: 2 | E103: The Book of Alchemy: A Creative Practice for an Inspired Life | F103: Suleika Jaouad | G103: Random House | H103: Traditional/established press | I103: B0DCFKK13P | J103: 12.99 | K103: 4.8 | L103: 997 | M103: 15771 | N103: N | O103: 315 | P103: 4.5 | Q103: 45769 | R103: =IF(Q103="","",($W$2-Q103)/30.44) -> 17.509855 | S103: AUDIO_DOWNLOAD, HARDCOVER, KINDLE | T103: #2 in Journaling; #10 in Creativity Self-Help; #12 in Journal Writing Self-Help | U103: https://www.amazon.com/dp/B0DCFKK13P
A104: =B104&"|"&D104 -> Journaling|3 | B104: Journaling | C104: 11650899011 | D104: 3 | E104: SNR: A dated six-year multilingual (FR/EN/AR) reflection journal (French Edition) | F104: STORDO | G104: (none listed) | H104: Indie (no publisher listed) | I104: B0H23JWKMS | J104: 4.99 | M104: 15931 | N104: Y | O104: 120 | P104: 2.9 | Q104: 46159 | R104: =IF(Q104="","",($W$2-Q104)/30.44) -> 4.6977661 | S104: KINDLE, PAPERBACK | T104: #1 in Personal Development & Self-Help in French; #3 in Journaling; #37 in Spiritual Self-Help (Kindle Store) | U104: https://www.amazon.com/dp/B0H23JWKMS
A105: =B105&"|"&D105 -> Journaling|4 | B105: Journaling | C105: 11650899011 | D105: 4 | E105: The 5 Levels of Leadership: Proven Steps to Maximize Your Potential | F105: John C. Maxwell | G105: Center Street | H105: Traditional/established press | I105: B004QZ9P7O | J105: 2.99 | K105: 4.7 | L105: 4797 | M105: 18779 | N105: N | O105: 305 | P105: 1.3 | Q105: 40820 | R105: =IF(Q105="","",($W$2-Q105)/30.44) -> 180.09198 | S105: AUDIO_DOWNLOAD, HARDCOVER, KINDLE, PAPERBACK | T105: #4 in Journaling; #10 in Christian Prayer (Kindle Store); #11 in Business Teams | U105: https://www.amazon.com/dp/B004QZ9P7O
A106: =B106&"|"&D106 -> Journaling|5 | B106: Journaling | C106: 11650899011 | D106: 5 | E106: NIV, Beautiful Word Bible, Updated Edition: 600+ Full-Color Illustrated Verses | F106: Zondervan | G106: Zondervan | H106: Traditional/established press | I106: B086BNRXM6 | J106: 22.99 | K106: 4.9 | L106: 6007 | M106: 29049 | N106: Y | O106: 1699 | P106: 102.5 | Q106: 43746 | R106: =IF(Q106="","",($W$2-Q106)/30.44) -> 83.968463 | S106: HARDCOVER, KINDLE | T106: #2 in Color in Art; #5 in Journaling; #8 in New International Christian Bibles | U106: https://www.amazon.com/dp/B086BNRXM6
A107: =B107&"|"&D107 -> Journaling|6 | B107: Journaling | C107: 11650899011 | D107: 6 | E107: The Creative Cure: How Finding and Freeing Your Inner Artist Can Heal Your Life (Hierophant Creative Healing) | F107: Jacob Nordby | G107: Hierophant Publishing | H107: Traditional/established press | I107: B085PZYKTT | J107: 0.99 | K107: 4.5 | L107: 610 | M107: 29062 | N107: N | O107: 216 | P107: 0.67 | Q107: 44243 | R107: =IF(Q107="","",($W$2-Q107)/30.44) -> 67.641261 | S107: AUDIO_DOWNLOAD, KINDLE, PAPERBACK | T107: #6 in Journaling; #9 in Psychology of Creativity & Genius; #12 in Developmental Psychology (Kindle Store) | U107: https://www.amazon.com/dp/B085PZYKTT
A108: =B108&"|"&D108 -> Journaling|7 | B108: Journaling | C108: 11650899011 | D108: 7 | E108: The Internal Family Systems Workbook: A Guide to Discover Your Self and Heal Your Parts (Sounds True Inner Workbooks) | F108: Richard C. Schwartz | G108: St. Martin's Essentials | H108: Traditional/established press | I108: B0D12S7RSD | J108: 12.99 | K108: 4.7 | L108: 728 | M108: 33979 | N108: Y | O108: 226 | P108: 1.8 | Q108: 45629 | R108: =IF(Q108="","",($W$2-Q108)/30.44) -> 22.109067 | S108: KINDLE, PAPERBACK | T108: #7 in Journaling; #20 in Journal Writing Self-Help; #24 in Mate Seeking (Kindle Store) | U108: https://www.amazon.com/dp/B0D12S7RSD
A109: =B109&"|"&D109 -> Journaling|8 | B109: Journaling | C109: 11650899011 | D109: 8 | E109: 365 Journal Prompts: Daily Writing Prompts for Personal Development Self-Reflection and Future Vision | F109: Stacey Myers | G109: (none listed) | H109: Indie (no publisher listed) | I109: B0D929W8GH | J109: 2.99 | K109: 4 | L109: 49 | M109: 44826 | N109: Y | O109: 49 | P109: 0.46 | Q109: 45480 | R109: =IF(Q109="","",($W$2-Q109)/30.44) -> 27.003942 | S109: KINDLE, PAPERBACK | T109: #3 in Journal Writing; #8 in 90-Minute Self-Help Short Reads; #8 in Journaling | U109: https://www.amazon.com/dp/B0D929W8GH
A110: =B110&"|"&D110 -> Journaling|9 | B110: Journaling | C110: 11650899011 | D110: 9 | E110: The Daily Stoic Journal: 366 Days of Writing and Reflection on the Art of Living | F110: Ryan Holiday | G110: Portfolio | H110: Traditional/established press | I110: B0F64WRMN1 | J110: 4.99 | K110: 4.7 | L110: 2767 | M110: 45248 | N110: N | O110: 328 | P110: 1.6 | Q110: 43053 | R110: =IF(Q110="","",($W$2-Q110)/30.44) -> 106.73456 | S110: HARDCOVER, KINDLE | T110: #9 in Journaling; #45 in Journal Writing Self-Help; #74 in Motivational Business Management | U110: https://www.amazon.com/dp/B0F64WRMN1
A111: =B111&"|"&D111 -> Journaling|10 | B111: Journaling | C111: 11650899011 | D111: 10 | E111: Gilmore Girls: The Rory Gilmore Reading Challenge: The Official Guide to All the Books | F111: Erika Berlin | G111: Running Press Adult | H111: Traditional/established press | I111: B0CTZMMWNF | J111: 2.99 | K111: 4.8 | L111: 121 | M111: 46288 | N111: N | O111: 251 | P111: 57.6 | Q111: 45594 | R111: =IF(Q111="","",($W$2-Q111)/30.44) -> 23.25887 | S111: HARDCOVER, KINDLE | T111: #5 in Comedy Television; #8 in General Books & Reading; #9 in Books & Reading Literary Criticism | U111: https://www.amazon.com/dp/B0CTZMMWNF
A112: =B112&"|"&D112 -> Journaling|11 | B112: Journaling | C112: 11650899011 | D112: 11 | E112: Layout Ideas 101: Over 100 inspiring journal layouts plus 500 writing prompts (Journal With Purpose) | F112: Helen Colebrook | G112: David & Charles | H112: Traditional/established press | I112: B093X22MKL | J112: 3.99 | K112: 4.5 | L112: 829 | M112: 46301 | N112: Y | O112: 127 | P112: 164.7 | Q112: 44299 | R112: =IF(Q112="","",($W$2-Q112)/30.44) -> 65.801577 | S112: KINDLE, PAPERBACK | T112: #11 in Journaling; #18 in Graphic Design Drawing; #31 in Creativity Self-Help | U112: https://www.amazon.com/dp/B093X22MKL
A113: =B113&"|"&D113 -> Journaling|12 | B113: Journaling | C113: 11650899011 | D113: 12 | E113: Give Me a Year: 12 New Things to Embrace Change and Live Your Best Life | F113: Shonda Scott | G113: Wonderwell Press | H113: Traditional/established press | I113: B0FN27R863 | J113: 9.99 | K113: 4.4 | L113: 32 | M113: 54983 | N113: N | O113: 155 | P113: 4.1 | Q113: 45916 | R113: =IF(Q113="","",($W$2-Q113)/30.44) -> 12.680683 | S113: AUDIO_DOWNLOAD, HARDCOVER, KINDLE, PAPERBACK | T113: #4 in Journal Writing; #7 in Inner Child; #12 in Journaling | U113: https://www.amazon.com/dp/B0FN27R863
A114: =B114&"|"&D114 -> Journaling|13 | B114: Journaling | C114: 11650899011 | D114: 13 | E114: The Forgiveness Journal: A Guided Journey to Forgiving What You Can't Forget (A Devotional Companion with Journaling Prompts to the #1 New York Times Bestseller) | F114: Lysa TerKeurst | G114: Thomas Nelson | H114: Traditional/established press | I114: B0989HS7WL | J114: 14.99 | K114: 4.8 | L114: 3443 | M114: 58821 | N114: Y | O114: 222 | P114: 16.8 | Q114: 44411 | R114: =IF(Q114="","",($W$2-Q114)/30.44) -> 62.122208 | S114: HARDCOVER, KINDLE | T114: #9 in Divorce (Books); #13 in Journaling; #22 in Adult Christian Education (Kindle Store) | U114: https://www.amazon.com/dp/B0989HS7WL
...

Sheet BSR_Table
A1: Kindle Store BSR | B1: Est. sales/day | C1: Label / source
A2: 1 | B2: 5000 | C2: Extrapolated anchor (bounds interpolation; not a measured value)
A3: 100 | B3: 1000 | C3: BookBloom calibration, Nov 2025
A4: 250 | B4: 500 | C4: BookBloom
A5: 500 | B5: 280 | C5: BookBloom
A6: 1000 | B6: 120 | C6: BookBloom
A7: 2000 | B7: 65 | C7: BookBloom
A8: 5000 | B8: 30 | C8: BookBloom
A9: 10000 | B9: 20 | C9: BookBloom
A10: 20000 | B10: 10 | C10: BookBloom
A11: 50000 | B11: 4 | C11: BookBloom
A12: 100000 | B12: 1.5 | C12: BookBloom
A13: 200000 | B13: 0.6 | C13: Extrapolated (log-log trend)
A14: 500000 | B14: 0.15 | C14: Extrapolated (log-log trend)
A16: Cross-check: Vappingo 2026 bands (BSR 2,000-10,000 ≈ 20-80/day; 10,000-50,000 ≈ 3-20/day) agree with this curve. See KR_Crosscheck for a test against Kindle Ranker's own estimates.

Sheet Sales_Estimates
A1: Inputs (edit blue cells)
A2: Estimate band (±) | B2: 0.4 | C2: Default ±40% around the curve estimate
A3: Delivery cost ($/MB, Amazon.com) | B3: 0.15 | C3: KDP Digital Book Pricing page, verified 2026-10-07
A4: 70% band minimum ($) | B4: 2.99 | C4: KDP, verified 2026-10-07
A5: 70% band maximum ($) | B5: 12.99 | C5: KDP, effective 2026-07-07
A6: Days per month | B6: 30 | C6: Assumption
A7: KENP rate ($/page, Aug 2026) | B7: 0.00517 | C7: Written Word Media, updated 2026-09-18
A9: Key | B9: Category | C9: Rank | D9: Title | E9: Publisher class | F9: Price ($) | G9: BSR | H9: File MB | I9: KU | J9: Bracket | K9: BSR low (b1) | L9: BSR high (b2) | M9: Sales low (s1) | N9: Sales high (s2) | O9: Est. sales/day | P9: Low/day | Q9: High/day | R9: Royalty/sale ($) | S9: Est. monthly units | T9: Est. monthly royalty ($) | U9: Low monthly royalty ($) | V9: High monthly royalty ($) | W9: Method
A10: =Charts_Snapshot!A2 -> Prayer|1 | B10: =Charts_Snapshot!B2 -> Prayer | C10: =Charts_Snapshot!D2 -> 1 | D10: =Charts_Snapshot!E2 -> Contemplative Prayer (Image Classic) | E10: =Charts_Snapshot!H2 -> Traditional/established press | F10: =Charts_Snapshot!J2 -> 1.99 | G10: =Charts_Snapshot!M2 -> 6841 | H10: =Charts_Snapshot!P2 -> 1.8 | I10: =Charts_Snapshot!N2 -> N | J10: =MIN(MATCH(G10,BSR_Table!$A$2:$A$14,1),12) -> 7 | K10: =INDEX(BSR_Table!$A$2:$A$14,J10) -> 5000 | L10: =INDEX(BSR_Table!$A$2:$A$14,J10+1) -> 10000 | M10: =INDEX(BSR_Table!$B$2:$B$14,J10) -> 30 | N10: =INDEX(BSR_Table!$B$2:$B$14,J10+1) -> 20 | O10: =EXP(LN(M10)+(LN(G10)-LN(K10))*(LN(N10)-LN(M10))/(LN(L10)-LN(K10))) -> 24.973468 | P10: =O10*(1-$B$2) -> 14.984081 | Q10: =O10*(1+$B$2) -> 34.962855 | R10: =IF(AND(F10>=$B$4,F10<=$B$5),MAX(0.7*F10-$B$3*H10,0.35*F10),0.35*F10) -> 0.6965 | S10: =O10*$B$6 -> 749.20403 | T10: =S10*R10 -> 521.82061 | U10: =P10*$B$6*R10 -> 313.09237 | V10: =Q10*$B$6*R10 -> 730.54885 | W10: Estimated: BSR curve (log-log), paid sales only; KU reads excluded; royalty assumes the better of 70% (minus delivery) or 35%
A11: =Charts_Snapshot!A3 -> Prayer|2 | B11: =Charts_Snapshot!B3 -> Prayer | C11: =Charts_Snapshot!D3 -> 2 | D11: =Charts_Snapshot!E3 -> Praying Like Monks, Living Like Fools: An Invitation to the Wonder and Mystery of Prayer | E11: =Charts_Snapshot!H3 -> Traditional/established press | F11: =Charts_Snapshot!J3 -> 4.99 | G11: =Charts_Snapshot!M3 -> 8407 | H11: =Charts_Snapshot!P3 -> 4.1 | I11: =Charts_Snapshot!N3 -> Y | J11: =MIN(MATCH(G11,BSR_Table!$A$2:$A$14,1),12) -> 7 | K11: =INDEX(BSR_Table!$A$2:$A$14,J11) -> 5000 | L11: =INDEX(BSR_Table!$A$2:$A$14,J11+1) -> 10000 | M11: =INDEX(BSR_Table!$B$2:$B$14,J11) -> 30 | N11: =INDEX(BSR_Table!$B$2:$B$14,J11+1) -> 20 | O11: =EXP(LN(M11)+(LN(G11)-LN(K11))*(LN(N11)-LN(M11))/(LN(L11)-LN(K11))) -> 22.136663 | P11: =O11*(1-$B$2) -> 13.281998 | Q11: =O11*(1+$B$2) -> 30.991328 | R11: =IF(AND(F11>=$B$4,F11<=$B$5),MAX(0.7*F11-$B$3*H11,0.35*F11),0.35*F11) -> 2.878 | S11: =O11*$B$6 -> 664.0999 | T11: =S11*R11 -> 1911.2795 | U11: =P11*$B$6*R11 -> 1146.7677 | V11: =Q11*$B$6*R11 -> 2675.7913 | W11: Estimated: BSR curve (log-log), paid sales only; KU reads excluded; royalty assumes the better of 70% (minus delivery) or 35%
A12: =Charts_Snapshot!A4 -> Prayer|3 | B12: =Charts_Snapshot!B4 -> Prayer | C12: =Charts_Snapshot!D4 -> 3 | D12: =Charts_Snapshot!E4 -> Praying the Names of God for 52 Weeks, Expanded Edition: A Year-Long Bible Study | E12: =Charts_Snapshot!H4 -> Traditional/established press | F12: =Charts_Snapshot!J4 -> 1.99 | G12: =Charts_Snapshot!M4 -> 10079 | H12: =Charts_Snapshot!P4 -> 9.2 | I12: =Charts_Snapshot!N4 -> N | J12: =MIN(MATCH(G12,BSR_Table!$A$2:$A$14,1),12) -> 8 | K12: =INDEX(BSR_Table!$A$2:$A$14,J12) -> 10000 | L12: =INDEX(BSR_Table!$A$2:$A$14,J12+1) -> 20000 | M12: =INDEX(BSR_Table!$B$2:$B$14,J12) -> 20 | N12: =INDEX(BSR_Table!$B$2:$B$14,J12+1) -> 10 | O12: =EXP(LN(M12)+(LN(G12)-LN(K12))*(LN(N12)-LN(M12))/(LN(L12)-LN(K12))) -> 19.843238 | P12: =O12*(1-$B$2) -> 11.905943 | Q12: =O12*(1+$B$2) -> 27.780534 | R12: =IF(AND(F12>=$B$4,F12<=$B$5),MAX(0.7*F12-$B$3*H12,0.35*F12),0.35*F12) -> 0.6965 | S12: =O12*$B$6 -> 595.29715 | T12: =S12*R12 -> 414.62447 | U12: =P12*$B$6*R12 -> 248.77468 | V12: =Q12*$B$6*R12 -> 580.47425 | W12: Estimated: BSR curve (log-log), paid sales only; KU reads excluded; royalty assumes the better of 70% (minus delivery) or 35%
A13: =Charts_Snapshot!A5 -> Prayer|4 | B13: =Charts_Snapshot!B5 -> Prayer | C13: =Charts_Snapshot!D5 -> 4 | D13: =Charts_Snapshot!E5 -> The Familiar Stranger: (Re)Introducing the Holy Spirit to Those in Search of an Experiential Spirituality | E13: =Charts_Snapshot!H5 -> Traditional/established press | F13: =Charts_Snapshot!J5 -> 3.99 | G13: =Charts_Snapshot!M5 -> 10680 | H13: =Charts_Snapshot!P5 -> 1.3 | I13: =Charts_Snapshot!N5 -> N | J13: =MIN(MATCH(G13,BSR_Table!$A$2:$A$14,1),12) -> 8 | K13: =INDEX(BSR_Table!$A$2:$A$14,J13) -> 10000 | L13: =INDEX(BSR_Table!$A$2:$A$14,J13+1) -> 20000 | M13: =INDEX(BSR_Table!$B$2:$B$14,J13) -> 20 | N13: =INDEX(BSR_Table!$B$2:$B$14,J13+1) -> 10 | O13: =EXP(LN(M13)+(LN(G13)-LN(K13))*(LN(N13)-LN(M13))/(LN(L13)-LN(K13))) -> 18.726592 | P13: =O13*(1-$B$2) -> 11.235955 | Q13: =O13*(1+$B$2) -> 26.217228 | R13: =IF(AND(F13>=$B$4,F13<=$B$5),MAX(0.7*F13-$B$3*H13,0.35*F13),0.35*F13) -> 2.598 | S13: =O13*$B$6 -> 561.79775 | T13: =S13*R13 -> 1459.5506 | U13: =P13*$B$6*R13 -> 875.73034 | V13: =Q13*$B$6*R13 -> 2043.3708 | W13: Estimated: BSR curve (log-log), paid sales only; KU reads excluded; royalty assumes the better of 70% (minus delivery) or 35%
A14: =Charts_Snapshot!A6 -> Prayer|5 | B14: =Charts_Snapshot!B6 -> Prayer | C14: =Charts_Snapshot!D6 -> 5 | D14: =Charts_Snapshot!E6 -> Breath as Prayer: Calm Your Anxiety, Focus Your Mind, and Renew Your Soul (80+ Breath Prayers and Devotional Meditations) | E14: =Charts_Snapshot!H6 -> Traditional/established press | F14: =Charts_Snapshot!J6 -> 3.99 | G14: =Charts_Snapshot!M6 -> 11490 | H14: =Charts_Snapshot!P6 -> 9.4 | I14: =Charts_Snapshot!N6 -> Y | J14: =MIN(MATCH(G14,BSR_Table!$A$2:$A$14,1),12) -> 8 | K14: =INDEX(BSR_Table!$A$2:$A$14,J14) -> 10000 | L14: =INDEX(BSR_Table!$A$2:$A$14,J14+1) -> 20000 | M14: =INDEX(BSR_Table!$B$2:$B$14,J14) -> 20 | N14: =INDEX(BSR_Table!$B$2:$B$14,J14+1) -> 10 | O14: =EXP(LN(M14)+(LN(G14)-LN(K14))*(LN(N14)-LN(M14))/(LN(L14)-LN(K14))) -> 17.40644 | P14: =O14*(1-$B$2) -> 10.443864 | Q14: =O14*(1+$B$2) -> 24.369017 | R14: =IF(AND(F14>=$B$4,F14<=$B$5),MAX(0.7*F14-$B$3*H14,0.35*F14),0.35*F14) -> 1.3965 | S14: =O14*$B$6 -> 522.19321 | T14: =S14*R14 -> 729.24282 | U14: =P14*$B$6*R14 -> 437.54569 | V14: =Q14*$B$6*R14 -> 1020.9399 | W14: Estimated: BSR curve (log-log), paid sales only; KU reads excluded; royalty assumes the better of 70% (minus delivery) or 35%
A15: =Charts_Snapshot!A7 -> Prayer|6 | B15: =Charts_Snapshot!B7 -> Prayer | C15: =Charts_Snapshot!D7 -> 6 | D15: =Charts_Snapshot!E7 -> Spiritual Warfare Prayers From the Psalms: Finding Strength, Protection, and Breakthrough in God's Word - A Devotional Guide for God's Covering, Provision, Wisdom, Courage, and Cleansing | E15: =Charts_Snapshot!H7 -> Indie (no publisher listed) | F15: =Charts_Snapshot!J7 -> 4.99 | G15: =Charts_Snapshot!M7 -> 11842 | H15: =Charts_Snapshot!P7 -> 2.3 | I15: =Charts_Snapshot!N7 -> Y | J15: =MIN(MATCH(G15,BSR_Table!$A$2:$A$14,1),12) -> 8 | K15: =INDEX(BSR_Table!$A$2:$A$14,J15) -> 10000 | L15: =INDEX(BSR_Table!$A$2:$A$14,J15+1) -> 20000 | M15: =INDEX(BSR_Table!$B$2:$B$14,J15) -> 20 | N15: =INDEX(BSR_Table!$B$2:$B$14,J15+1) -> 10 | O15: =EXP(LN(M15)+(LN(G15)-LN(K15))*(LN(N15)-LN(M15))/(LN(L15)-LN(K15))) -> 16.889039 | P15: =O15*(1-$B$2) -> 10.133423 | Q15: =O15*(1+$B$2) -> 23.644655 | R15: =IF(AND(F15>=$B$4,F15<=$B$5),MAX(0.7*F15-$B$3*H15,0.35*F15),0.35*F15) -> 3.148 | S15: =O15*$B$6 -> 506.67117 | T15: =S15*R15 -> 1595.0008 | U15: =P15*$B$6*R15 -> 957.00051 | V15: =Q15*$B$6*R15 -> 2233.0012 | W15: Estimated: BSR curve (log-log), paid sales only; KU reads excluded; royalty assumes the better of 70% (minus delivery) or 35%
A16: =Charts_Snapshot!A8 -> Prayer|7 | B16: =Charts_Snapshot!B8 -> Prayer | C16: =Charts_Snapshot!D8 -> 7 | D16: =Charts_Snapshot!E8 -> Principles of Prayer | E16: =Charts_Snapshot!H8 -> Traditional/established press | F16: =Charts_Snapshot!J8 -> 3.99 | G16: =Charts_Snapshot!M8 -> 12101 | H16: =Charts_Snapshot!P8 -> 0.53 | I16: =Charts_Snapshot!N8 -> N | J16: =MIN(MATCH(G16,BSR_Table!$A$2:$A$14,1),12) -> 8 | K16: =INDEX(BSR_Table!$A$2:$A$14,J16) -> 10000 | L16: =INDEX(BSR_Table!$A$2:$A$14,J16+1) -> 20000 | M16: =INDEX(BSR_Table!$B$2:$B$14,J16) -> 20 | N16: =INDEX(BSR_Table!$B$2:$B$14,J16+1) -> 10 | O16: =EXP(LN(M16)+(LN(G16)-LN(K16))*(LN(N16)-LN(M16))/(LN(L16)-LN(K16))) -> 16.52756 | P16: =O16*(1-$B$2) -> 9.9165358 | Q16: =O16*(1+$B$2) -> 23.138584 | R16: =IF(AND(F16>=$B$4,F16<=$B$5),MAX(0.7*F16-$B$3*H16,0.35*F16),0.35*F16) -> 2.7135 | S16: =O16*$B$6 -> 495.82679 | T16: =S16*R16 -> 1345.426 | U16: =P16*$B$6*R16 -> 807.2556 | V16: =Q16*$B$6*R16 -> 1883.5964 | W16: Estimated: BSR curve (log-log), paid sales only; KU reads excluded; royalty assumes the better of 70% (minus delivery) or 35%
A17: =Charts_Snapshot!A9 -> Prayer|8 | B17: =Charts_Snapshot!B9 -> Prayer | C17: =Charts_Snapshot!D9 -> 8 | D17: =Charts_Snapshot!E9 -> Pray First: The Transformative Power of a Life Built on Prayer | E17: =Charts_Snapshot!H9 -> Traditional/established press | F17: =Charts_Snapshot!J9 -> 2.99 | G17: =Charts_Snapshot!M9 -> 12423 | H17: =Charts_Snapshot!P9 -> 7.3 | I17: =Charts_Snapshot!N9 -> Y | J17: =MIN(MATCH(G17,BSR_Table!$A$2:$A$14,1),12) -> 8 | K17: =INDEX(BSR_Table!$A$2:$A$14,J17) -> 10000 | L17: =INDEX(BSR_Table!$A$2:$A$14,J17+1) -> 20000 | M17: =INDEX(BSR_Table!$B$2:$B$14,J17) -> 20 | N17: =INDEX(BSR_Table!$B$2:$B$14,J17+1) -> 10 | O17: =EXP(LN(M17)+(LN(G17)-LN(K17))*(LN(N17)-LN(M17))/(LN(L17)-LN(K17))) -> 16.099171 | P17: =O17*(1-$B$2) -> 9.6595025 | Q17: =O17*(1+$B$2) -> 22.538839 | R17: =IF(AND(F17>=$B$4,F17<=$B$5),MAX(0.7*F17-$B$3*H17,0.35*F17),0.35*F17) -> 1.0465 | S17: =O17*$B$6 -> 482.97513 | T17: =S17*R17 -> 505.43347 | U17: =P17*$B$6*R17 -> 303.26008 | V17: =Q17*$B$6*R17 -> 707.60686 | W17: Estimated: BSR curve (log-log), paid sales only; KU reads excluded; royalty assumes the better of 70% (minus delivery) or 35%
A18: =Charts_Snapshot!A10 -> Prayer|9 | B18: =Charts_Snapshot!B10 -> Prayer | C18: =Charts_Snapshot!D10 -> 9 | D18: =Charts_Snapshot!E10 -> The Game of Life and How to Play It: The Original Unabridged And Complete Edition (Florence Scovel Shinn Classics) | E18: =Charts_Snapshot!H10 -> Public-domain reprint | F18: =Charts_Snapshot!J10 -> 0.99 | G18: =Charts_Snapshot!M10 -> 12807 | H18: =Charts_Snapshot!P10 -> 0.41 | I18: =Charts_Snapshot!N10 -> N | J18: =MIN(MATCH(G18,BSR_Table!$A$2:$A$14,1),12) -> 8 | K18: =INDEX(BSR_Table!$A$2:$A$14,J18) -> 10000 | L18: =INDEX(BSR_Table!$A$2:$A$14,J18+1) -> 20000 | M18: =INDEX(BSR_Table!$B$2:$B$14,J18) -> 20 | N18: =INDEX(BSR_Table!$B$2:$B$14,J18+1) -> 10 | O18: =EXP(LN(M18)+(LN(G18)-LN(K18))*(LN(N18)-LN(M18))/(LN(L18)-LN(K18))) -> 15.61646 | P18: =O18*(1-$B$2) -> 9.3698758 | Q18: =O18*(1+$B$2) -> 21.863044 | R18: =IF(AND(F18>=$B$4,F18<=$B$5),MAX(0.7*F18-$B$3*H18,0.35*F18),0.35*F18) -> 0.3465 | S18: =O18*$B$6 -> 468.49379 | T18: =S18*R18 -> 162.3331 | U18: =P18*$B$6*R18 -> 97.399859 | V18: =Q18*$B$6*R18 -> 227.26634 | W18: Estimated: BSR curve (log-log), paid sales only; KU reads excluded; royalty assumes the better of 70% (minus delivery) or 35%
A19: =Charts_Snapshot!A11 -> Prayer|10 | B19: =Charts_Snapshot!B11 -> Prayer | C19: =Charts_Snapshot!D11 -> 10 | D19: =Charts_Snapshot!E11 -> A Shepherd Looks at Psalm 23: Discovering God's Love for You (Timeless Faith Classics) | E19: =Charts_Snapshot!H11 -> Traditional/established press | F19: =Charts_Snapshot!J11 -> 1.99 | G19: =Charts_Snapshot!M11 -> 12809 | H19: =Charts_Snapshot!P11 -> 12.5 | I19: =Charts_Snapshot!N11 -> Y | J19: =MIN(MATCH(G19,BSR_Table!$A$2:$A$14,1),12) -> 8 | K19: =INDEX(BSR_Table!$A$2:$A$14,J19) -> 10000 | L19: =INDEX(BSR_Table!$A$2:$A$14,J19+1) -> 20000 | M19: =INDEX(BSR_Table!$B$2:$B$14,J19) -> 20 | N19: =INDEX(BSR_Table!$B$2:$B$14,J19+1) -> 10 | O19: =EXP(LN(M19)+(LN(G19)-LN(K19))*(LN(N19)-LN(M19))/(LN(L19)-LN(K19))) -> 15.614021 | P19: =O19*(1-$B$2) -> 9.3684128 | Q19: =O19*(1+$B$2) -> 21.85963 | R19: =IF(AND(F19>=$B$4,F19<=$B$5),MAX(0.7*F19-$B$3*H19,0.35*F19),0.35*F19) -> 0.6965 | S19: =O19*$B$6 -> 468.42064 | T19: =S19*R19 -> 326.25498 | U19: =P19*$B$6*R19 -> 195.75299 | V19: =Q19*$B$6*R19 -> 456.75697 | W19: Estimated: BSR curve (log-log), paid sales only; KU reads excluded; royalty assumes the better of 70% (minus delivery) or 35%
A20: =Charts_Snapshot!A12 -> Prayer|11 | B20: =Charts_Snapshot!B12 -> Prayer | C20: =Charts_Snapshot!D12 -> 11 | D20: =Charts_Snapshot!E12 -> Trusting God with Today: A Daily Devotional for Building Confident Faith and Lasting Joy (365 Devotions - Inspiration for Every Day of the Year) (Devotionals from Charles F. Stanley) | E20: =Charts_Snapshot!H12 -> Traditional/established press | F20: =Charts_Snapshot!J12 -> 3.99 | G20: =Charts_Snapshot!M12 -> 16726 | H20: =Charts_Snapshot!P12 -> 1.1 | I20: =Charts_Snapshot!N12 -> Y | J20: =MIN(MATCH(G20,BSR_Table!$A$2:$A$14,1),12) -> 8 | K20: =INDEX(BSR_Table!$A$2:$A$14,J20) -> 10000 | L20: =INDEX(BSR_Table!$A$2:$A$14,J20+1) -> 20000 | M20: =INDEX(BSR_Table!$B$2:$B$14,J20) -> 20 | N20: =INDEX(BSR_Table!$B$2:$B$14,J20+1) -> 10 | O20: =EXP(LN(M20)+(LN(G20)-LN(K20))*(LN(N20)-LN(M20))/(LN(L20)-LN(K20))) -> 11.957432 | P20: =O20*(1-$B$2) -> 7.1744589 | Q20: =O20*(1+$B$2) -> 16.740404 | R20: =IF(AND(F20>=$B$4,F20<=$B$5),MAX(0.7*F20-$B$3*H20,0.35*F20),0.35*F20) -> 2.628 | S20: =O20*$B$6 -> 358.72295 | T20: =S20*R20 -> 942.7239 | U20: =P20*$B$6*R20 -> 565.63434 | V20: =Q20*$B$6*R20 -> 1319.8135 | W20: Estimated: BSR curve (log-log), paid sales only; KU reads excluded; royalty assumes the better of 70% (minus delivery) or 35%
A21: =Charts_Snapshot!A13 -> Prayer|12 | B21: =Charts_Snapshot!B13 -> Prayer | C21: =Charts_Snapshot!D13 -> 12 | D21: =Charts_Snapshot!E13 -> How to Hear God: A Simple Guide for Normal People | E21: =Charts_Snapshot!H13 -> Traditional/established press | F21: =Charts_Snapshot!J13 -> 1.99 | G21: =Charts_Snapshot!M13 -> 19206 | H21: =Charts_Snapshot!P13 -> 2.1 | I21: =Charts_Snapshot!N13 -> Y | J21: =MIN(MATCH(G21,BSR_Table!$A$2:$A$14,1),12) -> 8 | K21: =INDEX(BSR_Table!$A$2:$A$14,J21) -> 10000 | L21: =INDEX(BSR_Table!$A$2:$A$14,J21+1) -> 20000 | M21: =INDEX(BSR_Table!$B$2:$B$14,J21) -> 20 | N21: =INDEX(BSR_Table!$B$2:$B$14,J21+1) -> 10 | O21: =EXP(LN(M21)+(LN(G21)-LN(K21))*(LN(N21)-LN(M21))/(LN(L21)-LN(K21))) -> 10.413412 | P21: =O21*(1-$B$2) -> 6.2480475 | Q21: =O21*(1+$B$2) -> 14.578777 | R21: =IF(AND(F21>=$B$4,F21<=$B$5),MAX(0.7*F21-$B$3*H21,0.35*F21),0.35*F21) -> 0.6965 | S21: =O21*$B$6 -> 312.40237 | T21: =S21*R21 -> 217.58825 | U21: =P21*$B$6*R21 -> 130.55295 | V21: =Q21*$B$6*R21 -> 304.62356 | W21: Estimated: BSR curve (log-log), paid sales only; KU reads excluded; royalty assumes the better of 70% (minus delivery) or 35%
... A209: =Charts_Snapshot!A201 -> One-Hour Self-Help Short Reads|20 | B209: =Charts_Snapshot!B201 -> One-Hour Self-Help Short Reads | C209: =Charts_Snapshot!D201 -> 20 | D209: =Charts_Snapshot!E201 -> Not Crazy, Just Conditioned: Surviving Narcissistic Abuse and Reclaiming Your Power | E209: =Charts_Snapshot!H201 -> Indie (no publisher listed) | F209: =Charts_Snapshot!J201 -> 5.99 | G209: =Charts_Snapshot!M201 -> 170146 | H209: =Charts_Snapshot!P201 -> 3.9 | I209: =Charts_Snapshot!N201 -> N | J209: =MIN(MATCH(G209,BSR_Table!$A$2:$A$14,1),12) -> 11 | K209: =INDEX(BSR_Table!$A$2:$A$14,J209) -> 100000 | L209: =INDEX(BSR_Table!$A$2:$A$14,J209+1) -> 200000 | M209: =INDEX(BSR_Table!$B$2:$B$14,J209) -> 1.5 | N209: =INDEX(BSR_Table!$B$2:$B$14,J209+1) -> 0.6 | O209: =EXP(LN(M209)+(LN(G209)-LN(K209))*(LN(N209)-LN(M209))/(LN(L209)-LN(K209))) -> 0.74295329 | P209: =O209*(1-$B$2) -> 0.44577198 | Q209: =O209*(1+$B$2) -> 1.0401346 | R209: =IF(AND(F209>=$B$4,F209<=$B$5),MAX(0.7*F209-$B$3*H209,0.35*F209),0.35*F209) -> 3.608 | S209: =O209*$B$6 -> 22.288599 | T209: =S209*R209 -> 80.417264 | U209: =P209*$B$6*R209 -> 48.250359 | V209: =Q209*$B$6*R209 -> 112.58417 | W209: Estimated: BSR curve (log-log), paid sales only; KU reads excluded; royalty assumes the better of 70% (minus delivery) or 35%

Sheet Category_Competitiveness
A1: Category | B1: Node | C1: Snapshot #1 BSR | D1: Snapshot #20 BSR | E1: Est. #1 sales/day | F1: Est. #20 sales/day | G1: Indie titles in top 20 | H1: Indie titles ≤18 months old | I1: KU titles in top 20 | J1: Avg pages (top 20) | K1: Avg price ($) | L1: KR #1 sales/day | M1: KR #50 sales/day | N1: KR median price ($) | O1: KR avg pages | P1: KR indie % | Q1: KR KDP Select % | R1: KR monopoly | S1: MR sales/day to hold #1 | T1: MR sales/day for top 10 | U1: MR % indie | V1: Read
A2: Prayer | B2: 158562011 | C2: =INDEX(Charts_Snapshot!$M$2:$M$201,MATCH(A2&"|1",Charts_Snapshot!$A$2:$A$201,0)) -> 6841 | D2: =INDEX(Charts_Snapshot!$M$2:$M$201,MATCH(A2&"|20",Charts_Snapshot!$A$2:$A$201,0)) -> 33340 | E2: =INDEX(Sales_Estimates!$O$10:$O$209,MATCH(A2&"|1",Sales_Estimates!$A$10:$A$209,0)) -> 24.973468 | F2: =INDEX(Sales_Estimates!$O$10:$O$209,MATCH(A2&"|20",Sales_Estimates!$A$10:$A$209,0)) -> 5.9988002 | G2: =COUNTIFS(Charts_Snapshot!$B$2:$B$201,A2,Charts_Snapshot!$H$2:$H$201,"Indie*") -> 2 | H2: =COUNTIFS(Charts_Snapshot!$B$2:$B$201,A2,Charts_Snapshot!$H$2:$H$201,"Indie*",Charts_Snapshot!$R$2:$R$201,"<=18") -> 2 | I2: =COUNTIFS(Charts_Snapshot!$B$2:$B$201,A2,Charts_Snapshot!$N$2:$N$201,"Y") -> 13 | J2: =AVERAGEIFS(Charts_Snapshot!$O$2:$O$201,Charts_Snapshot!$B$2:$B$201,A2) -> 213.05 | K2: =AVERAGEIFS(Charts_Snapshot!$J$2:$J$201,Charts_Snapshot!$B$2:$B$201,A2) -> 4.388 | L2: 21 | M2: 1 | N2: 7.97 | O2: 214 | P2: 0.4 | Q2: 0.3333 | R2: Yes | S2: not measured | T2: not measured | U2: not measured | V2: Low-volume shelf (#1 ~25/day) dominated by Thomas Nelson/Zondervan, but two indie spiritual-warfare prayer books rank (BSR 11.8K, 27.2K) at 75-126pp.
A3: Stress Management | B3: 156574011 | C3: =INDEX(Charts_Snapshot!$M$2:$M$201,MATCH(A3&"|1",Charts_Snapshot!$A$2:$A$201,0)) -> 426 | D3: =INDEX(Charts_Snapshot!$M$2:$M$201,MATCH(A3&"|20",Charts_Snapshot!$A$2:$A$201,0)) -> 22588 | E3: =INDEX(Sales_Estimates!$O$10:$O$209,MATCH(A3&"|1",Sales_Estimates!$A$10:$A$209,0)) -> 320.14402 | F3: =INDEX(Sales_Estimates!$O$10:$O$209,MATCH(A3&"|20",Sales_Estimates!$A$10:$A$209,0)) -> 8.8542589 | G3: =COUNTIFS(Charts_Snapshot!$B$2:$B$201,A3,Charts_Snapshot!$H$2:$H$201,"Indie*") -> 5 | H3: =COUNTIFS(Charts_Snapshot!$B$2:$B$201,A3,Charts_Snapshot!$H$2:$H$201,"Indie*",Charts_Snapshot!$R$2:$R$201,"<=18") -> 4 | I3: =COUNTIFS(Charts_Snapshot!$B$2:$B$201,A3,Charts_Snapshot!$N$2:$N$201,"Y") -> 10 | J3: =AVERAGEIFS(Charts_Snapshot!$O$2:$O$201,Charts_Snapshot!$B$2:$B$201,A3) -> 247.85 | K3: =AVERAGEIFS(Charts_Snapshot!$J$2:$J$201,Charts_Snapshot!$B$2:$B$201,A3) -> 8.615 | L3: 105 | M3: 1 | N3: 9.99 | O3: 215 | P3: 0.35 | Q3: 0.4333 | R3: No | S3: not measured | T3: not measured | U3: not measured | V3: High demand at the top (Huberman #1). Indie entry point is #10-20 (~8-23/day). Two Sept-2026 indie launches ride $0.99 pricing.
A4: Self-Esteem | B4: 156572011 | C4: =INDEX(Charts_Snapshot!$M$2:$M$201,MATCH(A4&"|1",Charts_Snapshot!$A$2:$A$201,0)) -> 225 | D4: =INDEX(Charts_Snapshot!$M$2:$M$201,MATCH(A4&"|20",Charts_Snapshot!$A$2:$A$201,0)) -> 11053 | E4: =INDEX(Sales_Estimates!$O$10:$O$209,MATCH(A4&"|1",Sales_Estimates!$A$10:$A$209,0)) -> 541.48223 | F4: =INDEX(Sales_Estimates!$O$10:$O$209,MATCH(A4&"|20",Sales_Estimates!$A$10:$A$209,0)) -> 18.094635 | G4: =COUNTIFS(Charts_Snapshot!$B$2:$B$201,A4,Charts_Snapshot!$H$2:$H$201,"Indie*") -> 5 | H4: =COUNTIFS(Charts_Snapshot!$B$2:$B$201,A4,Charts_Snapshot!$H$2:$H$201,"Indie*",Charts_Snapshot!$R$2:$R$201,"<=18") -> 3 | I4: =COUNTIFS(Charts_Snapshot!$B$2:$B$201,A4,Charts_Snapshot!$N$2:$N$201,"Y") -> 9 | J4: =AVERAGEIFS(Charts_Snapshot!$O$2:$O$201,Charts_Snapshot!$B$2:$B$201,A4) -> 239.35 | K4: =AVERAGEIFS(Charts_Snapshot!$J$2:$J$201,Charts_Snapshot!$B$2:$B$201,A4) -> 6.9925 | L4: 57 | M4: 4 | N4: 10.49 | O4: 245 | P4: 0.25 | Q4: 0.4 | R4: No | S4: not measured | T4: not measured | U4: not measured | V4: Strongest indie shelf for guides: Chidiac, Trenton x2, Falces, Logan West all top 20. #20 still sells ~18/day.
A5: Motivational | B5: 156570011 | C5: =INDEX(Charts_Snapshot!$M$2:$M$201,MATCH(A5&"|1",Charts_Snapshot!$A$2:$A$201,0)) -> 225 | D5: =INDEX(Charts_Snapshot!$M$2:$M$201,MATCH(A5&"|20",Charts_Snapshot!$A$2:$A$201,0)) -> 4854 | E5: =INDEX(Sales_Estimates!$O$10:$O$209,MATCH(A5&"|1",Sales_Estimates!$A$10:$A$209,0)) -> 541.48223 | F5: =INDEX(Sales_Estimates!$O$10:$O$209,MATCH(A5&"|20",Sales_Estimates!$A$10:$A$209,0)) -> 30.759657 | G5: =COUNTIFS(Charts_Snapshot!$B$2:$B$201,A5,Charts_Snapshot!$H$2:$H$201,"Indie*") -> 1 | H5: =COUNTIFS(Charts_Snapshot!$B$2:$B$201,A5,Charts_Snapshot!$H$2:$H$201,"Indie*",Charts_Snapshot!$R$2:$R$201,"<=18") -> 0 | I5: =COUNTIFS(Charts_Snapshot!$B$2:$B$201,A5,Charts_Snapshot!$N$2:$N$201,"Y") -> 5 | J5: =AVERAGEIFS(Charts_Snapshot!$O$2:$O$201,Charts_Snapshot!$B$2:$B$201,A5) -> 259 | K5: =AVERAGEIFS(Charts_Snapshot!$J$2:$J$201,Charts_Snapshot!$B$2:$B$201,A5) -> 7.907 | L5: 173 | M5: 11 | N5: 9.99 | O5: 258 | P5: 0.15 | Q5: 0.3667 | R5: No | S5: 236–757 | T5: 29–83 | U5: 0.6 | V5: Classics and celebrity titles; #20 needs ~31/day. Only Meurisse's 2021 Dopamine Detox is indie. Not an entry shelf.
A6: Affirmations | B6: 202437591011 | C6: =INDEX(Charts_Snapshot!$M$2:$M$201,MATCH(A6&"|1",Charts_Snapshot!$A$2:$A$201,0)) -> 4802 | D6: =INDEX(Charts_Snapshot!$M$2:$M$201,MATCH(A6&"|20",Charts_Snapshot!$A$2:$A$201,0)) -> 75119 | E6: =INDEX(Sales_Estimates!$O$10:$O$209,MATCH(A6&"|1",Sales_Estimates!$A$10:$A$209,0)) -> 31.040491 | F6: =INDEX(Sales_Estimates!$O$10:$O$209,MATCH(A6&"|20",Sales_Estimates!$A$10:$A$209,0)) -> 2.2485883 | G6: =COUNTIFS(Charts_Snapshot!$B$2:$B$201,A6,Charts_Snapshot!$H$2:$H$201,"Indie*") -> 2 | H6: =COUNTIFS(Charts_Snapshot!$B$2:$B$201,A6,Charts_Snapshot!$H$2:$H$201,"Indie*",Charts_Snapshot!$R$2:$R$201,"<=18") -> 2 | I6: =COUNTIFS(Charts_Snapshot!$B$2:$B$201,A6,Charts_Snapshot!$N$2:$N$201,"Y") -> 7 | J6: =AVERAGEIFS(Charts_Snapshot!$O$2:$O$201,Charts_Snapshot!$B$2:$B$201,A6) -> 184.1 | K6: =AVERAGEIFS(Charts_Snapshot!$J$2:$J$201,Charts_Snapshot!$B$2:$B$201,A6) -> 6.503 | L6: n/a | M6: n/a | N6: n/a | O6: n/a | P6: n/a | Q6: n/a | R6: n/a | S6: not measured | T6: not measured | U6: not measured | V6: Thin shelf (#20 ~2/day). Public-domain reprints (Shinn, Allen) and classics. Cheap to rank; little to earn.
A7: Journaling | B7: 11650899011 | C7: =INDEX(Charts_Snapshot!$M$2:$M$201,MATCH(A7&"|1",Charts_Snapshot!$A$2:$A$201,0)) -> 2468 | D7: =INDEX(Charts_Snapshot!$M$2:$M$201,MATCH(A7&"|20",Charts_Snapshot!$A$2:$A$201,0)) -> 79982 | E7: =INDEX(Sales_Estimates!$O$10:$O$209,MATCH(A7&"|1",Sales_Estimates!$A$10:$A$209,0)) -> 54.432622 | F7: =INDEX(Sales_Estimates!$O$10:$O$209,MATCH(A7&"|20",Sales_Estimates!$A$10:$A$209,0)) -> 2.0575995 | G7: =COUNTIFS(Charts_Snapshot!$B$2:$B$201,A7,Charts_Snapshot!$H$2:$H$201,"Indie*") -> 6 | H7: =COUNTIFS(Charts_Snapshot!$B$2:$B$201,A7,Charts_Snapshot!$H$2:$H$201,"Indie*",Charts_Snapshot!$R$2:$R$201,"<=18") -> 3 | I7: =COUNTIFS(Charts_Snapshot!$B$2:$B$201,A7,Charts_Snapshot!$N$2:$N$201,"Y") -> 10 | J7: =AVERAGEIFS(Charts_Snapshot!$O$2:$O$201,Charts_Snapshot!$B$2:$B$201,A7) -> 263.65 | K7: =AVERAGEIFS(Charts_Snapshot!$J$2:$J$201,Charts_Snapshot!$B$2:$B$201,A7) -> 7.59 | L7: 12 | M7: 1 | N7: 5.99 | O7: 192 | P7: 0.55 | Q7: 0.7333 | R7: No | S7: not measured | T7: not measured | U7: not measured | V7: Low volume (#1 ~54/day, #20 ~2/day). Prompt books and Kindle Scribe journals appear; KU 10/20.
A8: Time Management | B8: 202437598011 | C8: =INDEX(Charts_Snapshot!$M$2:$M$201,MATCH(A8&"|1",Charts_Snapshot!$A$2:$A$201,0)) -> 1930 | D8: =INDEX(Charts_Snapshot!$M$2:$M$201,MATCH(A8&"|20",Charts_Snapshot!$A$2:$A$201,0)) -> 38918 | E8: =INDEX(Sales_Estimates!$O$10:$O$209,MATCH(A8&"|1",Sales_Estimates!$A$10:$A$209,0)) -> 67.080965 | F8: =INDEX(Sales_Estimates!$O$10:$O$209,MATCH(A8&"|20",Sales_Estimates!$A$10:$A$209,0)) -> 5.1390102 | G8: =COUNTIFS(Charts_Snapshot!$B$2:$B$201,A8,Charts_Snapshot!$H$2:$H$201,"Indie*") -> 4 | H8: =COUNTIFS(Charts_Snapshot!$B$2:$B$201,A8,Charts_Snapshot!$H$2:$H$201,"Indie*",Charts_Snapshot!$R$2:$R$201,"<=18") -> 3 | I8: =COUNTIFS(Charts_Snapshot!$B$2:$B$201,A8,Charts_Snapshot!$N$2:$N$201,"Y") -> 11 | J8: =AVERAGEIFS(Charts_Snapshot!$O$2:$O$201,Charts_Snapshot!$B$2:$B$201,A8) -> 305.95 | K8: =AVERAGEIFS(Charts_Snapshot!$J$2:$J$201,Charts_Snapshot!$B$2:$B$201,A8) -> 7.19 | L8: n/a | M8: n/a | N8: n/a | O8: n/a | P8: n/a | Q8: n/a | R8: n/a | S8: 29–80 | T8: 12–24 | U8: 0.7 | V8: Trad productivity classics plus indie ADHD workbooks at #19-20 and a Kindle Scribe planner at #10.
A9: Nutrition | B9: 156497011 | C9: =INDEX(Charts_Snapshot!$M$2:$M$201,MATCH(A9&"|1",Charts_Snapshot!$A$2:$A$201,0)) -> 1984 | D9: =INDEX(Charts_Snapshot!$M$2:$M$201,MATCH(A9&"|20",Charts_Snapshot!$A$2:$A$201,0)) -> 17516 | E9: =INDEX(Sales_Estimates!$O$10:$O$209,MATCH(A9&"|1",Sales_Estimates!$A$10:$A$209,0)) -> 65.463446 | F9: =INDEX(Sales_Estimates!$O$10:$O$209,MATCH(A9&"|20",Sales_Estimates!$A$10:$A$209,0)) -> 11.418132 | G9: =COUNTIFS(Charts_Snapshot!$B$2:$B$201,A9,Charts_Snapshot!$H$2:$H$201,"Indie*") -> 6 | H9: =COUNTIFS(Charts_Snapshot!$B$2:$B$201,A9,Charts_Snapshot!$H$2:$H$201,"Indie*",Charts_Snapshot!$R$2:$R$201,"<=18") -> 6 | I9: =COUNTIFS(Charts_Snapshot!$B$2:$B$201,A9,Charts_Snapshot!$N$2:$N$201,"Y") -> 8 | J9: =AVERAGEIFS(Charts_Snapshot!$O$2:$O$201,Charts_Snapshot!$B$2:$B$201,A9) -> 318.25 | K9: =AVERAGEIFS(Charts_Snapshot!$J$2:$J$201,Charts_Snapshot!$B$2:$B$201,A9) -> 5.542 | L9: 74 | M9: 3 | N9: 12.49 | O9: 320 | P9: 0.55 | Q9: 0.5667 | R9: No | S9: not measured | T9: not measured | U9: not measured | V9: Best indie shelf: 6 indie titles, all ≤18 months old, BSR 5.5K-17.5K. Trend-diet companions (cottage cheese, Dr O'Mara, GLP-1 era).
